Workbook

Sheet Sensor Unit
A3: System Parameters (defined by hardware) | E3: Profiles (usage of each component mode - defined by software and usage)
B4: form the datasheets
E5: "off" | F5: "sensing" | G5: "interactive"
A6: Processor | B6: https://github.com/liziying115-dev/Sleep-Environment-Recovery-Monitor/blob/main/datasheets/esp32-c3_datasheet.pdf
A7: Active | B7: 65.0003 | C7: mW | E7: 0 | F7: 0.0167 | G7: 1
A8: Idle | B8: 10.0002 | C8: mW | E8: 0 | F8: 0 | G8: 0
A9: Sleep | B9: 1.00035 | C9: mW | E9: 1 | F9: 0.9833 | G9: 0
A11: Sensor
A12: BME280 (Temp/Humid/Press) | B12: https://github.com/liziying115-dev/Sleep-Environment-Recovery-Monitor/blob/main/datasheets/bme280_datasheet.pdf
A13: Active | B13: 5 | C13: mW | E13: 0 | F13: 0.0167 | G13: 1
A14: Idle | B14: 0.0003 | C14: mW | E14: 1 | F14: 0.9833 | G14: 0
A16: VEML7700 (Light Sensor) | B16: https://github.com/liziying115-dev/Sleep-Environment-Recovery-Monitor/blob/main/datasheets/veml7700%E2%80%94%E2%80%94datasheet.pdf
A17: Active | B17: 5 | C17: mW | E17: 0 | F17: 0.0167 | G17: 1
A18: Idle | B18: 0.5 | C18: mW | E18: 1 | F18: 0.9833 | G18: 0
A20: SPH0645LM4H-B (Microphone) | B20: https://github.com/liziying115-dev/Sleep-Environment-Recovery-Monitor/blob/main/datasheets/sph0645lm4h_datasheet.pdf
A21: Active | B21: 5 | C21: mW | E21: 0 | F21: 0.0167 | G21: 1
A22: Idle | B22: 0.1 | C22: mW | E22: 1 | F22: 0.9833 | G22: 0
A24: Radio
A25: Data Rate | B25: 300 | C25: bps | L25: Total power in profile (mw) | O25: Maximum Time
A26: Standby Power | B26: 5.00002 | C26: mW | E26: 0 | F26: 0.0167 | G26: 0 | L26: =E5 -> "off" | M26: =SUMPRODUCT(B7:B28, E7:E28) -> 1.60065 | N26: mW | O26: =$M$31/M26 -> 5201.0121 | P26: hours
A27: TX Power | B27: 20.000003 | C27: mW | E27: 0 | F27: 0 | G27: 1 | L27: =F5 -> "sensing" | M27: =SUMPRODUCT(B7:B28, F7:F28) -> 2.9934245 | N27: mW | O27: =$M$31/M27 -> 2781.0957 | P27: hours
A28: RX Power | B28: 10.000001 | C28: mW | E28: 0 | F28: 0 | G28: 0 | L28: =G5 -> "interactive" | M28: =SUMPRODUCT(B7:B28, G7:G28) -> 100.0003 | N28: mW | O28: =$M$31/M28 -> 83.249748 | P28: hours
E30: 16 | F30: 7 | G30: =2/3600 -> 0.00055555556 | H30: hours/day typical usage | L30: Effective Battery Capacity
A31: Battery | M31: =B32*B33*B34 -> 8325 | N31: mW*h
A32: Capacity | B32: 2500 | C32: mAh
A33: Nominal Voltage | B33: 3.7 | C33: V | L33: Days of Use | M33: =M31/(E30*M26+F30*M27+G30*M28) -> 178.57171 | N33: days
A34: Regulator Efficiency | B34: 0.9 | L34: Hours of Use | M34: =M33*24 -> 4285.721 | N34: hours
A37: How did you determine your "days of use" metric ?
A38: I used a 6-step power budget calculation:
A39: 1. Extract power values from datasheets (ESP32-C3: 65mW active, 1mW sleep;
A40: sensors: 15mW total active, 0.6mW idle)
A41: 2. Define usage modes (off: 16hr, sensing: 7hr, interactive: 2sec per day)
A42: 3. Calculate duty cycles (sensing mode: 1.67% active, 98.33% sleep)
A43: 4. Compute weighted power per mode (off: 1.6mW, sensing: 2.99mW,
A44: interactive: 100mW)
A45: 5. Calculate daily energy: 46.62 mW*h per day
A46: 6. Battery life: 8325 mW*h ÷ 46.62 mW*h/day = 178 days
A48: What do you think is the optimum size for the battery in your device ?
A49: 2500-3000 mAh 18650 is optimal.
... A65: user in bed. Saves 5-10% power.

Sheet Display Unit
A3: System Parameters (defined by hardware) | E3: Profiles (usage of each component mode - defined by software and usage)
B4: form the datasheets
E5: "off" | F5: "sensing" | G5: "interactive"
A6: Processor | C6: https://github.com/liziying115-dev/Sleep-Environment-Recovery-Monitor/blob/main/datasheets/esp32-c3_datasheet.pdf
A7: Active | B7: 65.0003 | C7: mW | F7: 0.0028 | G7: 1
A8: Idle | B8: 10.0002 | C8: mW | E8: 0 | F8: 0 | G8: 0
A9: Sleep | B9: 1.00035 | C9: mW | E9: 1 | F9: 0.9972 | G9: 0
A11: LED
A12: On | B12: 5 | C12: mW | E12: 0 | F12: 0 | G12: 1
A14: Display (SSD1306 OLED) | C14: https://github.com/liziying115-dev/Sleep-Environment-Recovery-Monitor/blob/main/datasheets/ssd1306_datasheet.pdf
A15: On | B15: 20.00012 | C15: mW | E15: 0 | F15: 0 | G15: 1
A16: Off (leakage) | B16: 1.0006 | C16: mW | E16: 1 | F16: 1 | G16: 0
A18: Motor & Driver
A19: Active | B19: 300 | C19: mW | E19: 0 | F19: 0 | G19: 0.143
A20: Standby | B20: 5 | C20: mW | E20: 1 | F20: 1 | G20: 0.857
A24: Radio
A25: Data Rate | B25: 300 | C25: bps | L25: Total power in profile (mw) | O25: Maximum Time
A26: Standby Power | B26: 5.00002 | C26: mW | E26: 0 | F26: 0.0028 | G26: 1 | L26: =E5 -> "off" | M26: =SUMPRODUCT(B7:B28, E7:E28) -> 7.00095 | N26: mW | O26: =$M$31/M26 -> 1189.1243 | P26: hours
A27: TX Power | B27: 20.000003 | C27: mW | E27: 0 | F27: 0 | G27: 0 | L27: =F5 -> "sensing" | M27: =SUMPRODUCT(B7:B28, F7:F28) -> 7.2221499 | N27: mW | O27: =$M$31/M27 -> 1152.7038 | P27: hours
A28: RX Power | B28: 10.000001 | C28: mW | E28: 0 | F28: 0.0028 | G28: 0 | L28: =G5 -> "interactive" | M28: =SUMPRODUCT(B7:B28, G7:G28) -> 142.18544 | N28: mW | O28: =$M$31/M28 -> 58.550299 | P28: hours
E30: 23 | F30: 0.1 | G30: 0.0097 | H30: hours/day typical usage | L30: Effective Battery Capacity
A31: Battery | M31: =B32*B33*B34 -> 8325 | N31: mW*h
A32: Capacity | B32: 2500 | C32: mAh
A33: Nominal Voltage | B33: 3.7 | C33: V | L33: Days of Use | M33: =M31/(E30*M26+F30*M27+G30*M28) -> 51.035026 | N33: days
A34: Regulator Efficiency | B34: 0.9 | L34: Hours of Use | M34: =M33*24 -> 1224.8406 | N34: hours
A37: How did you determine your "days of use" metric ?
A38: Same methodology as Sensor Unit:
A39: 1. Component power from datasheets (ESP32-C3: 65mW, OLED: 20mW,
A40: LED: 5mW, Motor: 300mW active/5mW standby)
A41: 2. Usage modes (off: 23hr, sensing: 0.1hr, interactive: 35sec per day)
A42: 3. Duty cycles (sensing: 0.28% active, interactive: motor 14.3% of 35sec)
A43: 4. Weighted power (off: 7mW, sensing: 2.21mW, interactive: 137.9mW)
A44: 5. Daily energy: 162.6 mW*h per day
A45: 6. Battery life: 6660 mW*h ÷ 162.6 mW*h/day = 39 days
A47: What do you think is the optimum size for the battery in your device ?
A48: 2000 mAh LiPo or 18650 is optimal. Provides 39 days (13x the 3-day
A49: target), with margin for degradation and heavy usage. Motor driver
... A68: 5x battery improvement - highest ROI optimization.

Sheet Sensitivity Analysis_Sensor
A50: Linked Data from First Page DO NOT EDIT
A52: ='Sensor Unit'!A3 -> System Parameters (defined by hardware) | B52: ='Sensor Unit'!B3 | C52: ='Sensor Unit'!C3 | D52: ='Sensor Unit'!D3 | T52: ='Sensor Unit'!E3 -> Profiles (usage of each component mode - defined by software and usage) | U52: ='Sensor Unit'!F3 | V52: ='Sensor Unit'!G3 | W52: ='Sensor Unit'!H3
A53: ='Sensor Unit'!A4 | B53: ='Sensor Unit'!B4 -> form the datasheets | C53: ='Sensor Unit'!C4 | D53: ='Sensor Unit'!D4 | T53: ='Sensor Unit'!E4 | U53: ='Sensor Unit'!F4 | V53: ='Sensor Unit'!G4 | W53: ='Sensor Unit'!H4
A54: ='Sensor Unit'!A5 | B54: ='Sensor Unit'!B5 | C54: ='Sensor Unit'!C5 | D54: ='Sensor Unit'!D5 | T54: ='Sensor Unit'!E5 -> "off" | U54: ='Sensor Unit'!F5 -> "sensing" | V54: ='Sensor Unit'!G5 -> "interactive" | W54: ='Sensor Unit'!H5
A55: ='Sensor Unit'!A6 -> Processor | B55: ='Sensor Unit'!B6 -> https://github.com/liziying115-dev/Sleep-Environment-Recovery-Monitor/blob/main/datasheets/esp32-c3_datasheet.pdf | C55: ='Sensor Unit'!C6 | D55: ='Sensor Unit'!D6 | T55: ='Sensor Unit'!E6 | U55: ='Sensor Unit'!F6 | V55: ='Sensor Unit'!G6 | W55: ='Sensor Unit'!H6
A56: ='Sensor Unit'!A7 -> Active | B56: ='Sensor Unit'!B7 -> 65.0003 | C56: ='Sensor Unit'!C7 -> mW | D56: =$B56*0.9 -> 58.50027 | E56: =$B56 -> 65.0003 | F56: =$B56 -> 65.0003 | G56: =$B56 -> 65.0003 | H56: =$B56 -> 65.0003 | I56: =$B56 -> 65.0003 | J56: =$B56 -> 65.0003 | K56: =$B56 -> 65.0003 | L56: =$B56 -> 65.0003 | ... O56: =$B56 -> 65.0003 | T56: ='Sensor Unit'!E7 -> 0 | U56: ='Sensor Unit'!F7 -> 0.0167 | V56: ='Sensor Unit'!G7 -> 1 | W56: ='Sensor Unit'!H7
A57: ='Sensor Unit'!A8 -> Idle | B57: ='Sensor Unit'!B8 -> 10.0002 | C57: ='Sensor Unit'!C8 -> mW | D57: =$B57 -> 10.0002 | E57: =$B57*0.9 -> 9.00018 | F57: =$B57 -> 10.0002 | G57: =$B57 -> 10.0002 | H57: =$B57 -> 10.0002 | I57: =$B57 -> 10.0002 | J57: =$B57 -> 10.0002 | K57: =$B57 -> 10.0002 | L57: =$B57 -> 10.0002 | M57: =$B57 -> 10.0002 | ... O57: =$B57 -> 10.0002 | T57: ='Sensor Unit'!E8 -> 0 | U57: ='Sensor Unit'!F8 -> 0 | V57: ='Sensor Unit'!G8 -> 0 | W57: ='Sensor Unit'!H8
A58: ='Sensor Unit'!A9 -> Sleep | B58: ='Sensor Unit'!B9 -> 1.00035 | C58: ='Sensor Unit'!C9 -> mW | D58: =$B58 -> 1.00035 | E58: =$B58 -> 1.00035 | F58: =$B58*0.9 -> 0.900315 | G58: =$B58 -> 1.00035 | H58: =$B58 -> 1.00035 | I58: =$B58 -> 1.00035 | J58: =$B58 -> 1.00035 | K58: =$B58 -> 1.00035 | L58: =$B58 -> 1.00035 | M58: =$B58 -> 1.00035 | N58: =$B58 -> 1.00035 | O58: =$B58 -> 1.00035 | T58: ='Sensor Unit'!E9 -> 1 | U58: ='Sensor Unit'!F9 -> 0.9833 | V58: ='Sensor Unit'!G9 -> 0 | W58: ='Sensor Unit'!H9
A59: ='Sensor Unit'!A10 | B59: ='Sensor Unit'!B10 | C59: ='Sensor Unit'!C10 | D59: =$B59 | E59: =$B59 | F59: =$B59 | G59: =$B59 | H59: =$B59 | I59: =$B59 | J59: =$B59 | K59: =$B59 | ... O59: =$B59 | T59: ='Sensor Unit'!E10 | U59: ='Sensor Unit'!F10 | V59: ='Sensor Unit'!G10 | W59: ='Sensor Unit'!H10
W60: ='Sensor Unit'!H11
W61: ='Sensor Unit'!H12
W62: ='Sensor Unit'!H13
W63: ='Sensor Unit'!H14
A64: ='Sensor Unit'!A11 -> Sensor | B64: ='Sensor Unit'!B11 | C64: ='Sensor Unit'!C11 | D64: =$B64 | E64: =$B64 | F64: =$B64 | G64: =$B64 | H64: =$B64 | I64: =$B64 | J64: =$B64 | K64: =$B64 | ... O64: =$B64 | T64: ='Sensor Unit'!E11 | U64: ='Sensor Unit'!F11 | V64: ='Sensor Unit'!G11 | W64: ='Sensor Unit'!H15
A65: ='Sensor Unit'!A12 -> BME280 (Temp/Humid/Press) | B65: ='Sensor Unit'!B12 -> https://github.com/liziying115-dev/Sleep-Environment-Recovery-Monitor/blob/main/datasheets/bme280_datasheet.pdf | C65: ='Sensor Unit'!C12 | D65: =$B65 -> https://github.com/liziying115-dev/Sleep-Environment-Recovery-Monitor/blob/main/datasheets/bme280_datasheet.pdf | E65: =$B65 -> https://github.com/liziying115-dev/Sleep-Environment-Recovery-Monitor/blob/main/datasheets/bme280_datasheet.pdf | F65: =$B65 -> https://github.com/liziying115-dev/Sleep-Environment-Recovery-Monitor/blob/main/datasheets/bme280_datasheet.pdf | G65: =$B65 -> https://github.com/liziying115-dev/Sleep-Environment-Recovery-Monitor/blob/main/datasheets/bme280_datasheet.pdf | H65: =$B65*0.9 -> #VALUE! | I65: =$B65 -> https://github.com/liziying115-dev/Sleep-Environment-Recovery-Monitor/blob/main/datasheets/bme280_datasheet.pdf | J65: =$B65 -> https://github.com/liziying115-dev/Sleep-Environment-Recovery-Monitor/blob/main/datasheets/bme280_datasheet.pdf | K65: =$B65 -> https://github.com/liziying115-dev/Sleep-Environment-Recovery-Monitor/blob/main/datasheets/bme280_datasheet.pdf | L65: =$B65 -> https://github.com/liziying115-dev/Sleep-Environment-Recovery-Monitor/blob/main/datasheets/bme280_datasheet.pdf | M65: =$B65 -> https://github.com/liziying115-dev/Sleep-Environment-Recovery-Monitor/blob/main/datasheets/bme280_datasheet.pdf | N65: =$B65 -> https://github.com/liziying115-dev/Sleep-Environment-Recovery-Monitor/blob/main/datasheets/bme280_datasheet.pdf | O65: =$B65 -> https://github.com/liziying115-dev/Sleep-Environment-Recovery-Monitor/blob/main/datasheets/bme280_datasheet.pdf | T65: ='Sensor Unit'!E12 | U65: ='Sensor Unit'!F12 | V65: ='Sensor Unit'!G12 | W65: ='Sensor Unit'!H16
A66: ='Sensor Unit'!A13 -> Active | B66: ='Sensor Unit'!B13 -> 5 | C66: ='Sensor Unit'!C13 -> mW | D66: =$B66 -> 5 | E66: =$B66 -> 5 | F66: =$B66 -> 5 | G66: =$B66 -> 5 | H66: =$B66 -> 5 | I66: =$B66*0.9 -> 4.5 | J66: =$B66 -> 5 | K66: =$B66 -> 5 | L66: =$B66 -> 5 | M66: =$B66 -> 5 | N66: =$B66 -> 5 | O66: =$B66 -> 5 | T66: ='Sensor Unit'!E13 -> 0 | U66: ='Sensor Unit'!F13 -> 0.0167 | V66: ='Sensor Unit'!G13 -> 1 | W66: ='Sensor Unit'!H17
A67: ='Sensor Unit'!A14 -> Idle | B67: ='Sensor Unit'!B14 -> 0.0003 | C67: ='Sensor Unit'!C14 -> mW | D67: =$B67 -> 0.0003 | E67: =$B67 -> 0.0003 | F67: =$B67 -> 0.0003 | G67: =$B67 -> 0.0003 | H67: =$B67 -> 0.0003 | I67: =$B67 -> 0.0003 | J67: =$B67*0.9 -> 0.00027 | K67: =$B67 -> 0.0003 | L67: =$B67 -> 0.0003 | M67: =$B67 -> 0.0003 | N67: =$B67 -> 0.0003 | O67: =$B67 -> 0.0003 | T67: ='Sensor Unit'!E14 -> 1 | U67: ='Sensor Unit'!F14 -> 0.9833 | V67: ='Sensor Unit'!G14 -> 0 | W67: ='Sensor Unit'!H18
A68: ='Sensor Unit'!A16 -> VEML7700 (Light Sensor)
A69: ='Sensor Unit'!A17 -> Active | B69: ='Sensor Unit'!B17 -> 5 | C69: ='Sensor Unit'!C17 -> mW | D69: =$B69 -> 5 | E69: =$B69 -> 5 | F69: =$B69 -> 5 | G69: =$B69 -> 5 | H69: =$B69 -> 5 | I69: =$B69 -> 5 | J69: =$B69 -> 5 | K69: =$B69 -> 5 | ... O69: =$B69 -> 5 | T69: ='Sensor Unit'!E17 -> 0 | U69: ='Sensor Unit'!F17 -> 0.0167 | V69: ='Sensor Unit'!G17 -> 1 | W69: ='Sensor Unit'!H20
A70: ='Sensor Unit'!A18 -> Idle | B70: ='Sensor Unit'!B18 -> 0.5 | C70: ='Sensor Unit'!C18 -> mW | D70: =$B70 -> 0.5 | E70: =$B70 -> 0.5 | F70: =$B70 -> 0.5 | G70: =$B70 -> 0.5 | H70: =$B70 -> 0.5 | I70: =$B70 -> 0.5 | J70: =$B70 -> 0.5 | K70: =$B70*0.9 -> 0.45 | L70: =$B70 -> 0.5 | M70: =$B70 -> 0.5 | N70: =$B70 -> 0.5 | O70: =$B70 -> 0.5 | T70: ='Sensor Unit'!E18 -> 1 | U70: ='Sensor Unit'!F18 -> 0.9833 | V70: ='Sensor Unit'!G18 -> 0 | W70: ='Sensor Unit'!H21
A71: ='Sensor Unit'!A20 -> SPH0645LM4H-B (Microphone) | N71: =$B71 | O71: =$B71
A72: ='Sensor Unit'!A21 -> Active | B72: ='Sensor Unit'!B21 -> 5 | C72: ='Sensor Unit'!C21 -> mW | D72: =$B72 -> 5 | E72: =$B72 -> 5 | F72: =$B72 -> 5 | G72: =$B72 -> 5 | H72: =$B72 -> 5 | I72: =$B72 -> 5 | J72: =$B72 -> 5 | K72: =$B72 -> 5 | ... O72: =$B72 -> 5 | T72: ='Sensor Unit'!E21 -> 0 | U72: ='Sensor Unit'!F21 -> 0.0167 | V72: ='Sensor Unit'!G21 -> 1 | W72: ='Sensor Unit'!H23
A73: ='Sensor Unit'!A22 -> Idle | B73: 0.1 | C73: ='Sensor Unit'!C21 -> mW | D73: =$B73 -> 0.1 | E73: =$B73 -> 0.1 | F73: =$B73 -> 0.1 | G73: =$B73 -> 0.1 | H73: =$B73 -> 0.1 | I73: =$B73 -> 0.1 | J73: =$B73 -> 0.1 | K73: =$B73 -> 0.1 | ... O73: =$B73 -> 0.1 | T73: ='Sensor Unit'!E23 | U73: ='Sensor Unit'!F23 | V73: ='Sensor Unit'!G23 | W73: ='Sensor Unit'!H24
A74: ='Sensor Unit'!A26 -> Standby Power | B74: ='Sensor Unit'!B26 -> 5.00002 | C74: ='Sensor Unit'!C26 -> mW | D74: =$B74 -> 5.00002 | E74: =$B74 -> 5.00002 | F74: =$B74 -> 5.00002 | G74: =$B74 -> 5.00002 | H74: =$B74 -> 5.00002 | I74: =$B74 -> 5.00002 | J74: =$B74 -> 5.00002 | K74: =$B74 -> 5.00002 | L74: =$B74 -> 5.00002 | M74: =$B74*0.9 -> 4.500018 | N74: =$B74 -> 5.00002 | O74: =$B74 -> 5.00002 | T74: ='Sensor Unit'!E26 -> 0 | U74: ='Sensor Unit'!F26 -> 0.0167 | V74: ='Sensor Unit'!G26 -> 0 | W74: ='Sensor Unit'!H26
A75: ='Sensor Unit'!A27 -> TX Power | B75: ='Sensor Unit'!B27 -> 20.000003 | C75: ='Sensor Unit'!C27 -> mW | D75: =$B75 -> 20.000003 | E75: =$B75 -> 20.000003 | F75: =$B75 -> 20.000003 | G75: =$B75 -> 20.000003 | H75: =$B75 -> 20.000003 | I75: =$B75 -> 20.000003 | J75: =$B75 -> 20.000003 | K75: =$B75 -> 20.000003 | ... M75: =$B75 -> 20.000003 | N75: =$B75*0.9 -> 18.000003 | O75: =$B75 -> 20.000003 | T75: ='Sensor Unit'!E27 -> 0 | U75: ='Sensor Unit'!F27 -> 0 | V75: ='Sensor Unit'!G27 -> 1 | W75: ='Sensor Unit'!H27
A76: ='Sensor Unit'!A28 -> RX Power | B76: ='Sensor Unit'!B28 -> 10.000001 | C76: ='Sensor Unit'!C28 -> mW | D76: =$B76 -> 10.000001 | E76: =$B76 -> 10.000001 | F76: =$B76 -> 10.000001 | G76: =$B76 -> 10.000001 | H76: =$B76 -> 10.000001 | I76: =$B76 -> 10.000001 | J76: =$B76 -> 10.000001 | K76: =$B76 -> 10.000001 | ... N76: =$B76 -> 10.000001 | O76: =$B76*0.9 -> 9.0000009 | T76: ='Sensor Unit'!E28 -> 0 | U76: ='Sensor Unit'!F28 -> 0 | V76: ='Sensor Unit'!G28 -> 0 | W76: ='Sensor Unit'!H28
A77: ='Sensor Unit'!A29 | B77: ='Sensor Unit'!B29 | C77: ='Sensor Unit'!C29 | D77: ='Sensor Unit'!D29 | T77: ='Sensor Unit'!E29 | U77: ='Sensor Unit'!F29 | V77: ='Sensor Unit'!G29 | W77: ='Sensor Unit'!H29
A78: ='Sensor Unit'!A30 | B78: ='Sensor Unit'!B30 | C78: ='Sensor Unit'!C30 | D78: ='Sensor Unit'!D30 | T78: ='Sensor Unit'!E30 -> 16 | U78: ='Sensor Unit'!F30 -> 7 | V78: ='Sensor Unit'!G30 -> 0.00055555556 | W78: ='Sensor Unit'!H30 -> hours/day typical usage
A79: ='Sensor Unit'!A31 -> Battery | B79: ='Sensor Unit'!B31 | C79: ='Sensor Unit'!C31 | D79: ='Sensor Unit'!D31 | T79: ='Sensor Unit'!E31 | U79: ='Sensor Unit'!F31 | V79: ='Sensor Unit'!G31 | W79: ='Sensor Unit'!H31
A80: ='Sensor Unit'!A32 -> Capacity | B80: ='Sensor Unit'!B32 -> 2500 | C80: ='Sensor Unit'!C32 -> mAh | D80: ='Sensor Unit'!D32 | T80: ='Sensor Unit'!E32 | U80: ='Sensor Unit'!F32 | V80: ='Sensor Unit'!G32 | W80: ='Sensor Unit'!H32
A81: ='Sensor Unit'!A33 -> Nominal Voltage | B81: ='Sensor Unit'!B33 -> 3.7 | C81: ='Sensor Unit'!C33 -> V | D81: ='Sensor Unit'!D33 | T81: ='Sensor Unit'!E33 | U81: ='Sensor Unit'!F33 | V81: ='Sensor Unit'!G33 | W81: ='Sensor Unit'!H33
A82: ='Sensor Unit'!A34 -> Regulator Efficiency | B82: ='Sensor Unit'!B34 -> 0.9 | C82: ='Sensor Unit'!C34 | D82: ='Sensor Unit'!D34 | T82: ='Sensor Unit'!E34 | W82: ='Sensor Unit'!H34
A83: ='Sensor Unit'!A35 | B83: ='Sensor Unit'!B35 | C83: ='Sensor Unit'!C35 | D83: ='Sensor Unit'!D35 | O83: ='Sensor Unit'!E35 | P83: ='Sensor Unit'!F35 | Q83: ='Sensor Unit'!G35 | R83: ='Sensor Unit'!H35 | S83: ='Sensor Unit'!I35 | T83: ='Sensor Unit'!J35
A84: ='Sensor Unit'!A36 | B84: ='Sensor Unit'!B36 | C84: ='Sensor Unit'!C36 | D84: ='Sensor Unit'!D36 | O84: ='Sensor Unit'!E36 | P84: ='Sensor Unit'!F36 | Q84: ='Sensor Unit'!G36 | R84: ='Sensor Unit'!H36 | S84: ='Sensor Unit'!I36 | T84: ='Sensor Unit'!J36
A85: ='Sensor Unit'!A37 -> How did you determine your "days of use" metric ? | B85: ='Sensor Unit'!K24 | C85: ='Sensor Unit'!L24 | D85: ='Sensor Unit'!M24 | O85: ='Sensor Unit'!N24 | P85: ='Sensor Unit'!O24 | Q85: ='Sensor Unit'!P24 | R85: ='Sensor Unit'!Q24 | S85: ='Sensor Unit'!I37 | T85: ='Sensor Unit'!J37
A86: ='Sensor Unit'!A38 -> I used a 6-step power budget calculation: | B86: ='Sensor Unit'!K25 | R86: ='Sensor Unit'!Q25 | S86: ='Sensor Unit'!I38 | T86: ='Sensor Unit'!J38
A87: ='Sensor Unit'!L25 -> Total power in profile (mw) | B87: ='Sensor Unit'!M25 | C87: ='Sensor Unit'!N25 | R87: ='Sensor Unit'!Q26 | S87: ='Sensor Unit'!I39 | T87: ='Sensor Unit'!J39
A88: ='Sensor Unit'!L26 -> "off" | B88: =sumproduct(B56:B76, $T56:$T76) -> 1.50065 | C88: ='Sensor Unit'!N26 -> mW | D88: =sumproduct(D56:D76, $T56:$T76) -> 1.50065 | E88: =sumproduct(E56:E76, $T56:$T76) -> 1.50065 | F88: =sumproduct(F56:F76, $T56:$T76) -> 1.400615 | G88: =sumproduct(G56:G76, $T56:$T76) -> 1.50065 | H88: =sumproduct(H56:H76, $T56:$T76) -> #VALUE! | I88: =sumproduct(I56:I76, $T56:$T76) -> 1.50065 | J88: =sumproduct(J56:J76, $T56:$T76) -> 1.50062 | K88: =sumproduct(K56:K76, $T56:$T76) -> 1.45065 | ... O88: =sumproduct(O56:O76, $T56:$T76) -> 1.50065 | R88: ='Sensor Unit'!Q27 | S88: ='Sensor Unit'!I40 | T88: ='Sensor Unit'!J40 | U88: ='Sensor Unit'!K40 | V88: ='Sensor Unit'!L40
A89: ='Sensor Unit'!L27 -> "sensing" | B89: =sumproduct(B56:B76, $U56:$U76) -> 2.8950945 | C89: ='Sensor Unit'!N27 -> mW | D89: =sumproduct(D56:D76, $U56:$U76) -> 2.786544 | E89: =sumproduct(E56:E76, $U56:$U76) -> 2.8950945 | F89: =sumproduct(F56:F76, $U56:$U76) -> 2.7967301 | G89: =sumproduct(G56:G76, $U56:$U76) -> 2.8950945 | H89: =sumproduct(H56:H76, $U56:$U76) -> #VALUE! | I89: =sumproduct(I56:I76, $U56:$U76) -> 2.8867445 | J89: =sumproduct(J56:J76, $U56:$U76) -> 2.895065 | K89: =sumproduct(K56:K76, $U56:$U76) -> 2.8459295 | ... O89: =sumproduct(O56:O76, $U56:$U76) -> 2.8950945 | R89: ='Sensor Unit'!Q28 | S89: ='Sensor Unit'!I41 | T89: ='Sensor Unit'!J41 | U89: ='Sensor Unit'!K41 | V89: ='Sensor Unit'!L41
A90: ='Sensor Unit'!L28 -> "interactive" | B90: =sumproduct(B56:B76, $V56:$V76) -> 100.0003 | C90: ='Sensor Unit'!N28 -> mW | D90: =sumproduct(D56:D76, $V56:$V76) -> 93.500273 | E90: =sumproduct(E56:E76, $V56:$V76) -> 100.0003 | F90: =sumproduct(F56:F76, $V56:$V76) -> 100.0003 | G90: =sumproduct(G56:G76, $V56:$V76) -> 100.0003 | H90: =sumproduct(H56:H76, $V56:$V76) -> #VALUE! | I90: =sumproduct(I56:I76, $V56:$V76) -> 99.500303 | J90: =sumproduct(J56:J76, $V56:$V76) -> 100.0003 | K90: =sumproduct(K56:K76, $V56:$V76) -> 100.0003 | ... O90: =sumproduct(O56:O76, $V56:$V76) -> 100.0003 | R90: ='Sensor Unit'!Q29 | S90: ='Sensor Unit'!I42 | T90: ='Sensor Unit'!J42 | U90: ='Sensor Unit'!K42 | V90: ='Sensor Unit'!L42
...

Sheet Sensitivity Analysis_Display
A50: Linked Data from First Page DO NOT EDIT
A52: ='Sensor Unit'!A3 -> System Parameters (defined by hardware) | B52: ='Sensor Unit'!B3 | C52: ='Sensor Unit'!C3 | D52: ='Sensor Unit'!D3 | T52: ='Sensor Unit'!E3 -> Profiles (usage of each component mode - defined by software and usage) | U52: ='Sensor Unit'!F3 | V52: ='Sensor Unit'!G3 | W52: ='Sensor Unit'!H3
A53: ='Sensor Unit'!A4 | B53: ='Sensor Unit'!B4 -> form the datasheets | C53: ='Sensor Unit'!C4 | D53: ='Sensor Unit'!D4 | T53: ='Sensor Unit'!E4 | U53: ='Sensor Unit'!F4 | V53: ='Sensor Unit'!G4 | W53: ='Sensor Unit'!H4
A54: ='Sensor Unit'!A5 | B54: ='Sensor Unit'!B5 | C54: ='Sensor Unit'!C5 | D54: ='Sensor Unit'!D5 | T54: ='Sensor Unit'!E5 -> "off" | U54: ='Sensor Unit'!F5 -> "sensing" | V54: ='Sensor Unit'!G5 -> "interactive" | W54: ='Sensor Unit'!H5
A55: ='Sensor Unit'!A6 -> Processor | B55: ='Sensor Unit'!B6 -> https://github.com/liziying115-dev/Sleep-Environment-Recovery-Monitor/blob/main/datasheets/esp32-c3_datasheet.pdf | C55: ='Sensor Unit'!C6 | D55: ='Sensor Unit'!D6 | W55: ='Sensor Unit'!H6
A56: ='Sensor Unit'!A7 -> Active | B56: ='Sensor Unit'!B7 -> 65.0003 | C56: ='Sensor Unit'!C7 -> mW | D56: =$B56*0.9 -> 58.50027 | E56: =$B56 -> 65.0003 | F56: =$B56 -> 65.0003 | G56: =$B56 -> 65.0003 | H56: =$B56 -> 65.0003 | I56: =$B56 -> 65.0003 | J56: =$B56 -> 65.0003 | K56: =$B56 -> 65.0003 | L56: =$B56 -> 65.0003 | ... O56: =$B56 -> 65.0003 | T56: ='Sensor Unit'!E7 -> 0 | U56: ='Display Unit'!F7 -> 0.0028 | V56: ='Display Unit'!G7 -> 1 | W56: ='Sensor Unit'!H7
A57: ='Sensor Unit'!A8 -> Idle | B57: ='Sensor Unit'!B8 -> 10.0002 | C57: ='Sensor Unit'!C8 -> mW | D57: =$B57 -> 10.0002 | E57: =$B57*0.9 -> 9.00018 | F57: =$B57 -> 10.0002 | G57: =$B57 -> 10.0002 | H57: =$B57 -> 10.0002 | I57: =$B57 -> 10.0002 | J57: =$B57 -> 10.0002 | K57: =$B57 -> 10.0002 | L57: =$B57 -> 10.0002 | M57: =$B57 -> 10.0002 | ... O57: =$B57 -> 10.0002 | T57: ='Sensor Unit'!E8 -> 0 | U57: ='Display Unit'!F8 -> 0 | V57: ='Display Unit'!G8 -> 0
A58: ='Sensor Unit'!A9 -> Sleep | B58: ='Sensor Unit'!B9 -> 1.00035 | C58: ='Sensor Unit'!C9 -> mW | D58: =$B58 -> 1.00035 | E58: =$B58 -> 1.00035 | F58: =$B58*0.9 -> 0.900315 | G58: =$B58 -> 1.00035 | H58: =$B58 -> 1.00035 | I58: =$B58 -> 1.00035 | J58: =$B58 -> 1.00035 | K58: =$B58 -> 1.00035 | L58: =$B58 -> 1.00035 | M58: =$B58 -> 1.00035 | N58: =$B58 -> 1.00035 | O58: =$B58 -> 1.00035 | T58: ='Sensor Unit'!E9 -> 1 | U58: ='Display Unit'!F9 -> 0.9972 | V58: ='Display Unit'!G9 -> 0 | W58: ='Display Unit'!H9
T59: ='Sensor Unit'!E10 | W59: ='Sensor Unit'!H10
A60: ='Display Unit'!A11 -> LED | B60: ='Display Unit'!B11 | C60: ='Display Unit'!C11 | D60: ='Display Unit'!D11 | E60: ='Display Unit'!E11 | F60: ='Display Unit'!F11 | G60: ='Display Unit'!G11 | H60: ='Display Unit'!H11 | ... O60: ='Display Unit'!O11 | W60: ='Sensor Unit'!H11
A61: ='Display Unit'!A12 -> On | B61: ='Display Unit'!B12 -> 5 | C61: ='Display Unit'!C12 -> mW | D61: =B61 -> 5 | E61: =B61 -> 5 | F61: =D61 -> 5 | G61: =E61*0.9 -> 4.5 | H61: =F61 -> 5 | I61: =G61 -> 4.5 | J61: =H61 -> 5 | K61: =I61 -> 4.5 | L61: =J61 -> 5 | M61: =K61 -> 4.5 | N61: =L61 -> 5 | O61: =M61 -> 4.5 | W61: ='Sensor Unit'!H12
W62: ='Sensor Unit'!H13
W63: ='Sensor Unit'!H14
A64: ='Display Unit'!A14 -> Display (SSD1306 OLED) | B64: ='Display Unit'!B14 | C64: ='Display Unit'!C14 -> https://github.com/liziying115-dev/Sleep-Environment-Recovery-Monitor/blob/main/datasheets/ssd1306_datasheet.pdf | D64: ='Display Unit'!D14 | E64: ='Display Unit'!E14 | F64: ='Display Unit'!F14 | G64: ='Display Unit'!G14 | H64: ='Display Unit'!H14 | ... O64: ='Display Unit'!O14 | T64: ='Sensor Unit'!E11 | U64: ='Sensor Unit'!F11 | V64: ='Sensor Unit'!G11 | W64: ='Sensor Unit'!H15
A65: ='Display Unit'!A15 -> On | B65: ='Display Unit'!B15 -> 20.00012 | C65: ='Display Unit'!C15 -> mW | D65: =B65 -> 20.00012 | E65: =B65 -> 20.00012 | F65: =D65 -> 20.00012 | G65: =E65 -> 20.00012 | H65: =F65*0.9 -> 18.000108 | I65: =G65 -> 20.00012 | J65: =B65 -> 20.00012 | K65: =I65 -> 20.00012 | L65: =J65 -> 20.00012 | M65: =K65 -> 20.00012 | N65: =L65 -> 20.00012 | O65: =M65 -> 20.00012 | T65: ='Display Unit'!E15 -> 0 | U65: ='Display Unit'!F15 -> 0 | V65: ='Display Unit'!G15 -> 1 | W65: ='Sensor Unit'!H16
A66: ='Display Unit'!A16 -> Off (leakage) | B66: ='Display Unit'!B16 -> 1.0006 | C66: ='Display Unit'!C16 -> mW | D66: =B66 -> 1.0006 | E66: =B66 -> 1.0006 | F66: =D66 -> 1.0006 | G66: =E66 -> 1.0006 | H66: =F66 -> 1.0006 | I66: =G66*0.9 -> 0.90054 | J66: =H66 -> 1.0006 | K66: =B66 -> 1.0006 | L66: =J66 -> 1.0006 | M66: =K66 -> 1.0006 | N66: =L66 -> 1.0006 | O66: =M66 -> 1.0006 | T66: ='Display Unit'!E16 -> 1 | U66: ='Display Unit'!F16 -> 1 | V66: ='Display Unit'!G16 -> 0 | W66: ='Sensor Unit'!H17
A67: ='Display Unit'!A17 | B67: ='Display Unit'!B17 | C67: ='Display Unit'!C17 | T67: ='Display Unit'!E17 | W67: ='Sensor Unit'!H18
A68: ='Display Unit'!A18 -> Motor & Driver | B68: ='Display Unit'!B18 | C68: ='Display Unit'!C18
A69: ='Display Unit'!A19 -> Active | B69: ='Display Unit'!B19 -> 300 | C69: ='Display Unit'!C19 -> mW | D69: =B69 -> 300 | E69: =B69 -> 300 | F69: =D69 -> 300 | G69: =E69 -> 300 | H69: =F69 -> 300 | I69: =G69 -> 300 | J69: =H69*0.9 -> 270 | K69: =I69 -> 300 | L69: =B69 -> 300 | M69: =K69 -> 300 | N69: =L69 -> 300 | O69: =M69 -> 300 | T69: ='Display Unit'!E19 -> 0 | U69: ='Display Unit'!F19 -> 0 | V69: ='Display Unit'!G19 -> 0.143 | W69: ='Sensor Unit'!H20
A70: ='Display Unit'!A20 -> Standby | B70: ='Display Unit'!B20 -> 5 | C70: ='Display Unit'!C20 -> mW | D70: =B70 -> 5 | E70: =B70 -> 5 | F70: =D70 -> 5 | G70: =E70 -> 5 | H70: =F70 -> 5 | I70: =G70 -> 5 | J70: =H70 -> 5 | K70: =I70*0.9 -> 4.5 | L70: =J70 -> 5 | M70: =B70 -> 5 | N70: =L70 -> 5 | O70: =M70 -> 5 | T70: ='Display Unit'!E20 -> 1 | U70: ='Display Unit'!F20 -> 1 | V70: ='Display Unit'!G20 -> 0.857 | W70: ='Sensor Unit'!H21
A71: ='Display Unit'!A21 | B71: ='Display Unit'!B21 | C71: ='Display Unit'!C21
A72: ='Display Unit'!A22 | B72: ='Display Unit'!B22 | C72: ='Display Unit'!C22 | D72: ='Display Unit'!D22 | E72: ='Display Unit'!E22 | F72: ='Display Unit'!F22 | G72: ='Display Unit'!G22 | H72: ='Display Unit'!H22 | ... O72: ='Display Unit'!O22
A74: ='Sensor Unit'!A26 -> Standby Power | B74: ='Sensor Unit'!B26 -> 5.00002 | C74: ='Sensor Unit'!C26 -> mW | D74: =$B74 -> 5.00002 | E74: =$B74 -> 5.00002 | F74: =$B74 -> 5.00002 | G74: =$B74 -> 5.00002 | H74: =$B74 -> 5.00002 | I74: =$B74 -> 5.00002 | J74: =$B74 -> 5.00002 | K74: =$B74 -> 5.00002 | L74: =$B74 -> 5.00002 | M74: =$B74*0.9 -> 4.500018 | N74: =$B74 -> 5.00002 | O74: =$B74 -> 5.00002 | T74: ='Display Unit'!E26 -> 0 | U74: ='Display Unit'!F26 -> 0.0028 | V74: ='Display Unit'!G26 -> 1 | W74: ='Sensor Unit'!H26
A75: ='Sensor Unit'!A27 -> TX Power | B75: ='Sensor Unit'!B27 -> 20.000003 | C75: ='Sensor Unit'!C27 -> mW | D75: =$B75 -> 20.000003 | E75: =$B75 -> 20.000003 | F75: =$B75 -> 20.000003 | G75: =$B75 -> 20.000003 | H75: =$B75 -> 20.000003 | I75: =$B75 -> 20.000003 | J75: =$B75 -> 20.000003 | K75: =$B75 -> 20.000003 | ... M75: =$B75 -> 20.000003 | N75: =$B75*0.9 -> 18.000003 | O75: =$B75 -> 20.000003 | T75: ='Display Unit'!E27 -> 0 | V75: ='Display Unit'!G27 -> 0 | W75: ='Sensor Unit'!H27
A76: ='Sensor Unit'!A28 -> RX Power | B76: ='Sensor Unit'!B28 -> 10.000001 | C76: ='Sensor Unit'!C28 -> mW | D76: =$B76 -> 10.000001 | E76: =$B76 -> 10.000001 | F76: =$B76 -> 10.000001 | G76: =$B76 -> 10.000001 | H76: =$B76 -> 10.000001 | I76: =$B76 -> 10.000001 | J76: =$B76 -> 10.000001 | K76: =$B76 -> 10.000001 | ... N76: =$B76 -> 10.000001 | O76: =$B76*0.9 -> 9.0000009 | T76: ='Display Unit'!E28 -> 0 | U76: ='Display Unit'!F27 -> 0 | V76: ='Display Unit'!G28 -> 0 | W76: ='Sensor Unit'!H28
A77: ='Sensor Unit'!A29 | B77: ='Sensor Unit'!B29 | C77: ='Sensor Unit'!C29 | D77: ='Sensor Unit'!D29 | T77: ='Display Unit'!E29 | U77: ='Sensor Unit'!F29 | V77: ='Sensor Unit'!G29 | W77: ='Sensor Unit'!H29
A78: ='Sensor Unit'!A30 | B78: ='Sensor Unit'!B30 | C78: ='Sensor Unit'!C30 | D78: ='Sensor Unit'!D30 | T78: ='Display Unit'!E30 -> 23 | U78: ='Display Unit'!F30 -> 0.1 | V78: ='Display Unit'!G30 -> 0.0097 | W78: ='Sensor Unit'!H30 -> hours/day typical usage
A79: ='Sensor Unit'!A31 -> Battery | B79: ='Sensor Unit'!B31 | C79: ='Sensor Unit'!C31 | D79: ='Sensor Unit'!D31 | T79: ='Sensor Unit'!E31 | U79: ='Sensor Unit'!F31 | V79: ='Sensor Unit'!G31 | W79: ='Sensor Unit'!H31
A80: ='Sensor Unit'!A32 -> Capacity | B80: ='Sensor Unit'!B32 -> 2500 | C80: ='Sensor Unit'!C32 -> mAh | D80: ='Sensor Unit'!D32 | T80: ='Sensor Unit'!E32 | U80: ='Sensor Unit'!F32 | V80: ='Sensor Unit'!G32 | W80: ='Sensor Unit'!H32
A81: ='Sensor Unit'!A33 -> Nominal Voltage | B81: ='Sensor Unit'!B33 -> 3.7 | C81: ='Sensor Unit'!C33 -> V | D81: ='Sensor Unit'!D33 | T81: ='Sensor Unit'!E33 | U81: ='Sensor Unit'!F33 | V81: ='Sensor Unit'!G33 | W81: ='Sensor Unit'!H33
A82: ='Sensor Unit'!A34 -> Regulator Efficiency | B82: ='Sensor Unit'!B34 -> 0.9 | C82: ='Sensor Unit'!C34 | D82: ='Sensor Unit'!D34 | T82: ='Sensor Unit'!E34 | U82: ='Sensor Unit'!F34 | V82: ='Sensor Unit'!G34 | W82: ='Sensor Unit'!H34
A83: ='Sensor Unit'!A35 | B83: ='Sensor Unit'!B35 | C83: ='Sensor Unit'!C35 | D83: ='Sensor Unit'!D35 | O83: ='Sensor Unit'!E35 | P83: ='Sensor Unit'!F35 | Q83: ='Sensor Unit'!G35 | R83: ='Sensor Unit'!H35 | S83: ='Sensor Unit'!I35
A84: ='Sensor Unit'!A36 | R84: ='Sensor Unit'!H36 | S84: ='Sensor Unit'!I36
A85: ='Sensor Unit'!A37 -> How did you determine your "days of use" metric ? | R85: ='Sensor Unit'!Q24 | S85: ='Sensor Unit'!I37
A86: ='Sensor Unit'!A38 -> I used a 6-step power budget calculation: | R86: ='Sensor Unit'!Q25 | S86: ='Sensor Unit'!I38
A87: ='Sensor Unit'!L25 -> Total power in profile (mw) | B87: ='Sensor Unit'!M25 | C87: ='Sensor Unit'!N25 | R87: ='Sensor Unit'!Q26 | S87: ='Sensor Unit'!I39
A88: ='Sensor Unit'!L26 -> "off" | B88: =sumproduct(B56:B76, $T56:$T76) -> 7.00095 | C88: ='Sensor Unit'!N26 -> mW | D88: =sumproduct(D56:D76, $T56:$T76) -> 7.00095 | E88: =sumproduct(E56:E76, $T56:$T76) -> 7.00095 | F88: =sumproduct(F56:F76, $T56:$T76) -> 6.900915 | G88: =sumproduct(G56:G76, $T56:$T76) -> 7.00095 | H88: =sumproduct(H56:H76, $T56:$T76) -> 7.00095 | I88: =sumproduct(I56:I76, $T56:$T76) -> 6.90089 | J88: =sumproduct(J56:J76, $T56:$T76) -> 7.00095 | K88: =sumproduct(K56:K76, $T56:$T76) -> 6.50095 | ... O88: =sumproduct(O56:O76, $T56:$T76) -> 7.00095 | R88: ='Sensor Unit'!Q27 | S88: ='Sensor Unit'!I40
A89: ='Sensor Unit'!L27 -> "sensing" | B89: =sumproduct(B56:B76,$U56:$U76) -> 7.1941499 | C89: ='Sensor Unit'!N27 -> mW | D89: =sumproduct(D56:D76,$U56:$U76) -> 7.1759498 | E89: =sumproduct(E56:E76,$U56:$U76) -> 7.1941499 | F89: =sumproduct(F56:F76,$U56:$U76) -> 7.094395 | G89: =sumproduct(G56:G76,$U56:$U76) -> 7.1941499 | H89: =sumproduct(H56:H76,$U56:$U76) -> 7.1941499 | I89: =sumproduct(I56:I76,$U56:$U76) -> 7.0940899 | J89: =sumproduct(J56:J76,$U56:$U76) -> 7.1941499 | K89: =sumproduct(K56:K76,$U56:$U76) -> 6.6941499 | ... O89: =sumproduct(O56:O76,$U56:$U76) -> 7.1941499 | R89: ='Sensor Unit'!Q28 | S89: ='Sensor Unit'!I41
A90: ='Sensor Unit'!L28 -> "interactive" | B90: =sumproduct(B56:B76, $V56:$V76) -> 137.18544 | C90: ='Sensor Unit'!N28 -> mW | D90: =sumproduct(D56:D76, $V56:$V76) -> 130.68541 | E90: =sumproduct(E56:E76, $V56:$V76) -> 137.18544 | F90: =sumproduct(F56:F76, $V56:$V76) -> 137.18544 | G90: =sumproduct(G56:G76, $V56:$V76) -> 137.18544 | H90: =sumproduct(H56:H76, $V56:$V76) -> 135.18543 | I90: =sumproduct(I56:I76, $V56:$V76) -> 137.18544 | J90: =sumproduct(J56:J76, $V56:$V76) -> 132.89544 | K90: =sumproduct(K56:K76, $V56:$V76) -> 136.75694 | ... O90: =sumproduct(O56:O76, $V56:$V76) -> 137.18544 | R90: ='Sensor Unit'!Q29 | S90: ='Sensor Unit'!I42
A91: ='Sensor Unit'!L29 | B91: ='Sensor Unit'!M29 | C91: ='Sensor Unit'!N29 | D91: ='Sensor Unit'!O29 | E91: ='Sensor Unit'!P29 | F91: ='Sensor Unit'!Q30 | G91: ='Sensor Unit'!I43 | H91: ='Sensor Unit'!J43 | I91: ='Sensor Unit'!K43 | J91: ='Sensor Unit'!L43 | K91: ='Sensor Unit'!M43 | L91: ='Sensor Unit'!N43 | M91: ='Sensor Unit'!O43 | N91: ='Sensor Unit'!P43 | O91: ='Sensor Unit'!Q43 | R91: ='Sensor Unit'!Q30 | S91: ='Sensor Unit'!I43
...
